Workbook

Sheet Communes_HDF
A1: Code_INSEE | B1: Commune | C1: Departement | D1: EPCI | E1: Code_EPCI | F1: Population | G1: Superficie_km2 | H1: Densite_hab_km2 | I1: Taille_commune
A2: 02001 | B2: Abbécourt | C2: Aisne | D2: CA Chauny Tergnier La Fère | E2: 200071785 | F2: 518 | G2: 5.98 | H2: 86.6 | I2: 500 a 2 000
A3: 02002 | B3: Achery | C3: Aisne | D3: CA Chauny Tergnier La Fère | E3: 200071785 | F3: 584 | G3: 6.95 | H3: 84 | I3: 500 a 2 000
A4: 02003 | B4: Acy | C4: Aisne | D4: CA GrandSoissons Agglomération | E4: 240200477 | F4: 1004 | G4: 11.55 | H4: 86.9 | I4: 500 a 2 000
A5: 02004 | B5: Agnicourt-et-Séchelles | C5: Aisne | D5: CC du Pays de la Serre | E5: 240200469 | F5: 189 | G5: 10.72 | H5: 17.6 | I5: < 500 hab.
A6: 02005 | B6: Aguilcourt | C6: Aisne | D6: CC de la Champagne Picarde | E6: 240200576 | F6: 417 | G6: 10.61 | H6: 39.3 | I6: < 500 hab.
A7: 02006 | B7: Aisonville-et-Bernoville | C7: Aisne | D7: CC Thiérache Sambre et Oise | E7: 200071983 | F7: 259 | G7: 8.71 | H7: 29.7 | I7: < 500 hab.
A8: 02007 | B8: Aizelles | C8: Aisne | D8: CC du Chemin des Dames | E8: 240200592 | F8: 118 | G8: 4.88 | H8: 24.2 | I8: < 500 hab.
A9: 02008 | B9: Aizy-Jouy | C9: Aisne | D9: CC du Val de l'Aisne | E9: 240200501 | F9: 306 | G9: 14.72 | H9: 20.8 | I9: < 500 hab.
A10: 02009 | B10: Alaincourt | C10: Aisne | D10: CC du Val de l'Oise | E10: 200040426 | F10: 517 | G10: 5.99 | H10: 86.3 | I10: 500 a 2 000
A11: 02010 | B11: Allemant | C11: Aisne | D11: CC du Val de l'Aisne | E11: 240200501 | F11: 163 | G11: 5.16 | H11: 31.6 | I11: < 500 hab.
A12: 02011 | B12: Ambleny | C12: Aisne | D12: CC Retz en Valois | E12: 200071991 | F12: 1205 | G12: 17.24 | H12: 69.9 | I12: 500 a 2 000
A13: 02012 | B13: Ambrief | C13: Aisne | D13: CC du Canton d'Oulchy-le-Château | E13: 240200519 | F13: 79 | G13: 4.48 | H13: 17.6 | I13: < 500 hab.
... A3783: 80485 | B3783: Ô-de-Selle | C3783: Somme | D3783: CC Somme Sud-Ouest | E3783: 200071181 | F3783: 1148 | G3783: 26.94 | H3783: 42.6 | I3783: 500 a 2 000

Sheet Communes_HDF (2)
A1: Code_INSEE | B1: Commune | C1: Departement | D1: EPCI | E1: Code_EPCI | F1: Population | G1: Superficie_km2 | H1: Densite_hab_km2 | I1: Taille_commune
A2: 02001 | B2: Abbécourt | C2: Aisne | D2: CA Chauny Tergnier La Fère | E2: 200071785 | F2: 518 | G2: 5.98 | H2: 86.6 | I2: 500 a 2 000
A3: 02002 | B3: Achery | C3: Aisne | D3: CA Chauny Tergnier La Fère | E3: 200071785 | F3: 584 | G3: 6.95 | H3: 84 | I3: 500 a 2 000
A4: 02003 | B4: Acy | C4: Aisne | D4: CA GrandSoissons Agglomération | E4: 240200477 | F4: 1004 | G4: 11.55 | H4: 86.9 | I4: 500 a 2 000
A5: 02004 | B5: Agnicourt-et-Séchelles | C5: Aisne | D5: CC du Pays de la Serre | E5: 240200469 | F5: 189 | G5: 10.72 | H5: 17.6 | I5: < 500 hab.
A6: 02005 | B6: Aguilcourt | C6: Aisne | D6: CC de la Champagne Picarde | E6: 240200576 | F6: 417 | G6: 10.61 | H6: 39.3 | I6: < 500 hab.
A7: 02006 | B7: Aisonville-et-Bernoville | C7: Aisne | D7: CC Thiérache Sambre et Oise | E7: 200071983 | F7: 259 | G7: 8.71 | H7: 29.7 | I7: < 500 hab.
A8: 02007 | B8: Aizelles | C8: Aisne | D8: CC du Chemin des Dames | E8: 240200592 | F8: 118 | G8: 4.88 | H8: 24.2 | I8: < 500 hab.
A9: 02008 | B9: Aizy-Jouy | C9: Aisne | D9: CC du Val de l'Aisne | E9: 240200501 | F9: 306 | G9: 14.72 | H9: 20.8 | I9: < 500 hab.
A10: 02009 | B10: Alaincourt | C10: Aisne | D10: CC du Val de l'Oise | E10: 200040426 | F10: 517 | G10: 5.99 | H10: 86.3 | I10: 500 a 2 000
A11: 02010 | B11: Allemant | C11: Aisne | D11: CC du Val de l'Aisne | E11: 240200501 | F11: 163 | G11: 5.16 | H11: 31.6 | I11: < 500 hab.
A12: 02011 | B12: Ambleny | C12: Aisne | D12: CC Retz en Valois | E12: 200071991 | F12: 1205 | G12: 17.24 | H12: 69.9 | I12: 500 a 2 000
A13: 02012 | B13: Ambrief | C13: Aisne | D13: CC du Canton d'Oulchy-le-Château | E13: 240200519 | F13: 79 | G13: 4.48 | H13: 17.6 | I13: < 500 hab.
... A3783: 80485 | B3783: Ô-de-Selle | C3783: Somme | D3783: CC Somme Sud-Ouest | E3783: 200071181 | F3783: 1148 | G3783: 26.94 | H3783: 42.6 | I3783: 500 a 2 000

Sheet Marche_immobilier_2024
A1: Code_INSEE | B1: Commune | C1: Departement | D1: Nb_ventes_2024 | E1: Prix_median_m2 | F1: Prix_moyen_m2 | G1: Prix_median_vente
A2: 02001 | B2: Abbécourt | C2: Aisne | D2: 6 | E2: 810 | F2: 889 | G2: 107500
A3: 02002 | B3: Achery | C3: Aisne | D3: 8 | E3: 1169 | F3: 1259 | G3: 113975
A4: 02003 | B4: Acy | C4: Aisne | D4: 11 | E4: 1611 | F4: 1439 | G4: 125000
A5: 02011 | B5: Ambleny | C5: Aisne | D5: 16 | E5: 1636 | F5: 1752 | G5: 190000
A6: 02014 | B6: Amigny-Rouy | C6: Aisne | D6: 9 | E6: 1061 | F6: 1155 | G6: 140000
A7: 02018 | B7: Anizy-le-Grand | C7: Aisne | D7: 30 | E7: 1114 | F7: 1194 | G7: 115200
A8: 02020 | B8: Any-Martin-Rieux | C8: Aisne | D8: 5 | E8: 500 | F8: 470 | G8: 115000
A9: 02027 | B9: Assis-sur-Serre | C9: Aisne | D9: 8 | E9: 787 | F9: 869 | G9: 159975
A10: 02028 | B10: Athies-sous-Laon | C10: Aisne | D10: 26 | E10: 1432 | F10: 1376 | G10: 137600
A11: 02031 | B11: Aubenton | C11: Aisne | D11: 5 | E11: 611 | F11: 691 | G11: 80000
A12: 02037 | B12: Aulnois-sous-Laon | C12: Aisne | D12: 12 | E12: 1200 | F12: 1213 | G12: 134400
A13: 02041 | B13: Autreville | C13: Aisne | D13: 8 | E13: 986 | F13: 1154 | G13: 148500
... A1813: 80295 | B1813: Étinehem-Méricourt | C1813: Somme | D1813: 6 | E1813: 1009 | F1813: 1116 | G1813: 73000

Sheet Dictionnaire
A1: Colonne | B1: Type | C1: Description
A2: Code_INSEE | B2: Texte | C2: Code officiel de la commune (5 caracteres, garder le zero initial)
A3: Commune | B3: Texte | C3: Nom officiel de la commune
A4: Departement | B4: Texte | C4: Aisne, Nord, Oise, Pas-de-Calais ou Somme
A5: EPCI | B5: Texte | C5: Intercommunalite de rattachement (communaute de communes, d'agglomeration, metropole)
A6: Code_EPCI | B6: Texte | C6: Code SIREN de l EPCI
A7: Population | B7: Entier | C7: Population municipale en vigueur (source INSEE via API Geo)
A8: Superficie_km2 | B8: Decimal | C8: Superficie de la commune en km2
A9: Densite_hab_km2 | B9: Decimal | C9: Population / Superficie_km2 - calcule
A10: Taille_commune | B10: Texte | C10: Tranche de population, 5 modalites
A11: Nb_ventes_2024 | B11: Entier | C11: Nombre de ventes de logements en 2024 (communes a 5 ventes minimum)
A12: Prix_median_m2 | B12: Decimal (EUR) | C12: Prix au m2 median des logements vendus en 2024
... A14: Prix_median_vente | B14: Decimal (EUR) | C14: Prix de vente median d un logement en 2024

Sheet Sources
A1: Onglet | B1: Indicateur | C1: Producteur | D1: URL | E1: Licence
A2: Communes_HDF | B2: Population, superficie, EPCI | C2: API Geo (Etalab) - millesime INSEE en vigueur | D2: https://geo.api.gouv.fr/communes | E2: Licence Ouverte 2.0
A3: Marche_immobilier_2024 | B3: Ventes de logements 2024, prix au m2 | C3: DVF geolocalisees (Etalab / DGFiP) | D3: https://files.data.gouv.fr/geo-dvf/latest/csv/2024/departements/ | E3: Licence Ouverte 2.0
A4: A aller chercher | B4: Emploi, chomage, diplomes, revenus | C4: INSEE - Dossier complet par commune | D4: https://www.insee.fr/fr/statistiques/zones/2011101 | E4: Licence Ouverte
A5: A aller chercher | B5: Equipements et services (commerces, sante, ecoles) | C5: INSEE - Base permanente des equipements (BPE) | D5: https://www.insee.fr/fr/statistiques/3568638 | E5: Licence Ouverte
A6: A aller chercher | B6: Equipements sportifs | C6: Ministere des Sports - Data ES | D6: https://www.data.gouv.fr/datasets/recensement-des-equipements-sportifs-espaces-et-sites-de-pratiques | E6: Licence Ouverte
A7: A aller chercher | B7: Resultats electoraux, budgets communaux, subventions | C7: data.gouv.fr - recherche par mot-cle | D7: https://www.data.gouv.fr/datasets/ | E7: variable
A8: A aller chercher | B8: Donnees regionales Hauts-de-France | C8: Geo2France / Open data regional | D8: https://www.geo2france.fr/ | E8: Licence Ouverte

Sheet INSEE_Communes
A1: Code_INSEE | B1: Commune | C1: Population_2017 | D1: Population_2023 | E1: Niveau_vie_median_2023 | F1: Taux_pauvrete_2023
A2: 02001 | B2: Abbécourt | C2: 498 | D2: 518 | E2: 24700 | F2: non publié
A3: 02002 | B3: Achery | C3: 598 | D3: 584 | E3: 25260 | F3: non publié
A4: 02003 | B4: Acy | C4: 1012 | D4: 1004 | E4: 26000 | F4: non publié
A5: 02004 | B5: Agnicourt-et-Séchelles | C5: 177 | D5: 189 | E5: 21320 | F5: non publié
A6: 02005 | B6: Aguilcourt | C6: 384 | D6: 417 | E6: 27790 | F6: non publié
A7: 02006 | B7: Aisonville-et-Bernoville | C7: 255 | D7: 259 | E7: 25470 | F7: non publié
A8: 02007 | B8: Aizelles | C8: 125 | D8: 118 | E8: 26000 | F8: non publié
A9: 02008 | B9: Aizy-Jouy | C9: 291 | D9: 306 | E9: 26290 | F9: non publié
A10: 02009 | B10: Alaincourt | C10: 543 | D10: 517 | E10: 25820 | F10: non publié
A11: 02010 | B11: Allemant | C11: 177 | D11: =SOMME.SI.ENS('INSEE_Communes'!C2:C3783, | E11: 26140 | F11: non publié
A12: 02011 | B12: Ambleny | C12: 1155 | D12: 1205 | E12: 27570 | F12: non publié
A13: 02012 | B13: Ambrief | C13: 70 | D13: 79 | E13: non publié | F13: non publié
A14: 02013 | B14: Amifontaine | C14: 404 | D14: 391 | E14: 27200 | F14: non publié
A15: 02014 | B15: Amigny-Rouy | C15: 744 | D15: 707 | E15: 25340 | F15: non publié
A16: 02015 | B16: Ancienville | C16: 75 | D16: 78 | E16: non publié | F16: non publié
A17: 02016 | B17: Andelain | C17: 228 | D17: 212 | E17: 24940 | F17: non publié
A18: 02017 | B18: Anguilcourt-le-Sart | C18: 315 | D18: 274 | E18: 25510 | F18: non publié
A19: 02018 | B19: Anizy-le-Grand | C19: 2533 | D19: 2472 | E19: 23090 | F19: 16
A20: 02019 | B20: Annois | C20: 364 | D20: 349 | E20: 23740 | F20: non publié
A21: 02020 | B21: Any-Martin-Rieux | C21: 456 | D21: 456 | E21: 23100 | F21: non publié
A22: 02021 | B22: Archon | C22: 87 | D22: 76 | E22: non publié | F22: non publié
A23: 02022 | B23: Arcy-Sainte-Restitue | C23: 403 | D23: 396 | E23: 25950 | F23: non publié
A24: 02023 | B24: Armentières-sur-Ourcq | C24: 103 | D24: 96 | E24: non publié | F24: non publié
A25: 02024 | B25: Arrancy | C25: 53 | D25: 45 | E25: non publié | F25: non publié
A26: 02025 | B26: Artemps | C26: 371 | D26: 361 | E26: 26150 | F26: non publié
A27: 02027 | B27: Assis-sur-Serre | C27: 222 | D27: 209 | E27: 22280 | F27: non publié
A28: 02028 | B28: Athies-sous-Laon | C28: 2604 | D28: 2578 | E28: 25840 | F28: 11
A29: 02029 | B29: Attilly | C29: 363 | D29: 337 | E29: 27020 | F29: non publié
A30: 02030 | B30: Aubencheul-aux-Bois | C30: 269 | D30: 238 | E30: 25630 | F30: non publié
A31: 02031 | B31: Aubenton | C31: 657 | D31: 658 | E31: 20520 | F31: non publié
A32: 02032 | B32: Aubigny-aux-Kaisnes | C32: 253 | D32: 231 | E32: 21870 | F32: non publié
A33: 02033 | B33: Aubigny-en-Laonnois | C33: 105 | D33: 102 | E33: 27820 | F33: non publié
A34: 02034 | B34: Audignicourt | C34: 118 | D34: 104 | E34: 26480 | F34: non publié
A35: 02035 | B35: Audigny | C35: 279 | D35: 273 | E35: 24790 | F35: non publié
A36: 02036 | B36: Augy | C36: 82 | D36: 72 | E36: non publié | F36: non publié
A37: 02037 | B37: Aulnois-sous-Laon | C37: 1422 | D37: 1348 | E37: 24480 | F37: non publié
A38: 02038 | B38: Les Autels | C38: 57 | D38: 62 | E38: non publié | F38: non publié
A39: 02039 | B39: Autremencourt | C39: 169 | D39: 176 | E39: 21760 | F39: non publié
A40: 02040 | B40: Autreppes | C40: 178 | D40: 175 | E40: 23920 | F40: non publié
...

Sheet INSEE_Communes (2)
A1: Code_INSEE | B1: Commune | C1: Population_2017 | D1: Population_2023 | E1: Niveau_vie_median_2023 | F1: Taux_pauvrete_2023
A2: 02001 | B2: Abbécourt | C2: 498 | D2: 518 | E2: 24700 | F2: non publié
A3: 02002 | B3: Achery | C3: 598 | D3: 584 | E3: 25260 | F3: non publié
A4: 02003 | B4: Acy | C4: 1012 | D4: 1004 | E4: 26000 | F4: non publié
A5: 02004 | B5: Agnicourt-et-Séchelles | C5: 177 | D5: 189 | E5: 21320 | F5: non publié
A6: 02005 | B6: Aguilcourt | C6: 384 | D6: 417 | E6: 27790 | F6: non publié
A7: 02006 | B7: Aisonville-et-Bernoville | C7: 255 | D7: 259 | E7: 25470 | F7: non publié
A8: 02007 | B8: Aizelles | C8: 125 | D8: 118 | E8: 26000 | F8: non publié
A9: 02008 | B9: Aizy-Jouy | C9: 291 | D9: 306 | E9: 26290 | F9: non publié
A10: 02009 | B10: Alaincourt | C10: 543 | D10: 517 | E10: 25820 | F10: non publié
A11: 02010 | B11: Allemant | C11: 177 | D11: =SOMME.SI.ENS('INSEE_Communes'!C2:C3783, | E11: 26140 | F11: non publié
A12: 02011 | B12: Ambleny | C12: 1155 | D12: 1205 | E12: 27570 | F12: non publié
A13: 02012 | B13: Ambrief | C13: 70 | D13: 79 | E13: non publié | F13: non publié
A14: 02013 | B14: Amifontaine | C14: 404 | D14: 391 | E14: 27200 | F14: non publié
A15: 02014 | B15: Amigny-Rouy | C15: 744 | D15: 707 | E15: 25340 | F15: non publié
A16: 02015 | B16: Ancienville | C16: 75 | D16: 78 | E16: non publié | F16: non publié
A17: 02016 | B17: Andelain | C17: 228 | D17: 212 | E17: 24940 | F17: non publié
A18: 02017 | B18: Anguilcourt-le-Sart | C18: 315 | D18: 274 | E18: 25510 | F18: non publié
A19: 02018 | B19: Anizy-le-Grand | C19: 2533 | D19: 2472 | E19: 23090 | F19: 16
A20: 02019 | B20: Annois | C20: 364 | D20: 349 | E20: 23740 | F20: non publié
A21: 02020 | B21: Any-Martin-Rieux | C21: 456 | D21: 456 | E21: 23100 | F21: non publié
A22: 02021 | B22: Archon | C22: 87 | D22: 76 | E22: non publié | F22: non publié
A23: 02022 | B23: Arcy-Sainte-Restitue | C23: 403 | D23: 396 | E23: 25950 | F23: non publié
A24: 02023 | B24: Armentières-sur-Ourcq | C24: 103 | D24: 96 | E24: non publié | F24: non publié
A25: 02024 | B25: Arrancy | C25: 53 | D25: 45 | E25: non publié | F25: non publié
A26: 02025 | B26: Artemps | C26: 371 | D26: 361 | E26: 26150 | F26: non publié
A27: 02027 | B27: Assis-sur-Serre | C27: 222 | D27: 209 | E27: 22280 | F27: non publié
A28: 02028 | B28: Athies-sous-Laon | C28: 2604 | D28: 2578 | E28: 25840 | F28: 11
A29: 02029 | B29: Attilly | C29: 363 | D29: 337 | E29: 27020 | F29: non publié
A30: 02030 | B30: Aubencheul-aux-Bois | C30: 269 | D30: 238 | E30: 25630 | F30: non publié
A31: 02031 | B31: Aubenton | C31: 657 | D31: 658 | E31: 20520 | F31: non publié
A32: 02032 | B32: Aubigny-aux-Kaisnes | C32: 253 | D32: 231 | E32: 21870 | F32: non publié
A33: 02033 | B33: Aubigny-en-Laonnois | C33: 105 | D33: 102 | E33: 27820 | F33: non publié
A34: 02034 | B34: Audignicourt | C34: 118 | D34: 104 | E34: 26480 | F34: non publié
A35: 02035 | B35: Audigny | C35: 279 | D35: 273 | E35: 24790 | F35: non publié
A36: 02036 | B36: Augy | C36: 82 | D36: 72 | E36: non publié | F36: non publié
A37: 02037 | B37: Aulnois-sous-Laon | C37: 1422 | D37: 1348 | E37: 24480 | F37: non publié
A38: 02038 | B38: Les Autels | C38: 57 | D38: 62 | E38: non publié | F38: non publié
A39: 02039 | B39: Autremencourt | C39: 169 | D39: 176 | E39: 21760 | F39: non publié
A40: 02040 | B40: Autreppes | C40: 178 | D40: 175 | E40: 23920 | F40: non publié
...

Sheet INSEE_EPCI
A1: Code_EPCI | B1: Nom_EPCI | C1: Population_2017 | D1: Population_2023 | E1: Niveau_vie_median_2023 | F1: Taux_pauvrete_2023
A2: 248000531 | B2: CA Amiens Métropole | C2: 180816 | D2: 184392 | E2: 23640 | F2: 23.5
A3: 200071785 | B3: CA Chauny Tergnier La Fère | C3: 55470 | D3: 54027 | E3: 22590 | F3: 21.6
A4: 245901152 | B4: CA Coeur d'Ostrevent | C4: 70957 | D4: 69764 | E4: 22340 | F4: 21.1
A5: 200040947 | B5: CA Coeur de Flandre | C5: 102272 | D5: 102743 | E5: 25990 | F5: 11.1
A6: 200068047 | B6: CA Creil Sud Oise | C6: 86512 | D6: 90234 | E6: 19250 | F6: 33.5
A7: 200044618 | B7: CA Douaisis Agglo | C7: 149258 | D7: 149282 | E7: 22540 | F7: 22.4
A8: 200090751 | B8: CA Grand Calais Terres et Mers | C8: 105269 | D8: 98895 | E8: 22150 | F8: 23
A9: 240200477 | B9: CA GrandSoissons Agglomération | C9: 52328 | D9: 51809 | E9: 22560 | F9: 23.9
A10: 200043396 | B10: CA Maubeuge Val de Sambre | C10: 125651 | D10: 122247 | E10: 20580 | F10: 28.6
A11: 245901160 | B11: CA Valenciennes Métropole | C11: 192594 | D11: 191738 | E11: 22000 | F11: 25
A12: 246200299 | B12: CA d'Hénin-Carvin | C12: 125835 | D12: 125793 | E12: 21790 | F12: 23.3
A13: 200072460 | B13: CA de Béthune-Bruay, Artois-Lys Romane | C13: 276895 | D13: 275028 | E13: 22990 | F13: 19.4
... A91: 200033579 | B91: CU d'Arras | C91: 107763 | D91: 109884 | E91: 25670 | F91: 16.5
A92: 245900428 | B92: CU de Dunkerque | C92: 196901 | D92: 191478 | E92: 23270 | F92: 20.3 | J92: =AVERAGE(INSEE_EPCI!F2:F93) -> 16.086957
A93: 200093201 | B93: Métropole Européenne de Lille | C93: 1170630 | D93: 1195234 | E93: 24430 | F93: 21.4 | J93: =SUMPRODUCT(INSEE_EPCI!F2:F93, INSEE_EPCI!D2:D93) / SUM(INSEE_EPCI!D2:D93) -> 19.063895

Sheet INSEE_Source
A1: Élément | B1: Valeur
A2: Producteur | B2: INSEE
A3: Jeu de données | B3: Base du comparateur de territoires
A4: Page | B4: https://www.insee.fr/fr/statistiques/2521169
A5: Millésimes | B5: Revenus : Filosofi 2023 · Population : recensements 2017 et 2023 · géographie au 1er janvier 2026
A6: Licence | B6: Licence Ouverte 2.0 (Etalab)
A7: Date d'extraction | B7: 24/09/2026
A8: Périmètre | B8: Hauts-de-France : 3 782 communes (onglet Communes) et 92 intercommunalités (onglet EPCI)
A9: Colonnes | B9: Niveau_vie_median_2023 : niveau de vie médian, en euros par an · Taux_pauvrete_2023 : part de la population sous le seuil de pauvreté (60 % du niveau de vie médian national), en %
A10: Valeurs « non publié » | B10: Le niveau de vie et le taux de pauvreté ne sont pas publiés pour les petites communes (secret statistique) : ces cases contiennent le texte « non publié ». Taux de pauvreté publié pour 520 communes, et pour les 92 intercommunalités.
A11: Préparation | B11: Extrait filtré sur les Hauts-de-France du fichier complet (2,9 millions de lignes), mis en colonnes. Aucune valeur modifiée.

Sheet Jointure
A1: Code_INSEE | B1: Commune | C1: Taux_pauvrete
A2: =Communes_HDF!A2 -> 02001 | B2: =Communes_HDF!B2 -> Abbécourt | C2: =_xlfn.XLOOKUP(A2, INSEE_Communes!$A$2:$A$3783, INSEE_Communes!$F$2:$F$3783, "code introuvable") -> non publié
A3: =Communes_HDF!A3 -> 02002 | B3: =Communes_HDF!B3 -> Achery | C3: =_xlfn.XLOOKUP(A3, INSEE_Communes!$A$2:$A$3783, INSEE_Communes!$F$2:$F$3783, "code introuvable") -> non publié
A4: =Communes_HDF!A4 -> 02003 | B4: =Communes_HDF!B4 -> Acy | C4: =_xlfn.XLOOKUP(A4, INSEE_Communes!$A$2:$A$3783, INSEE_Communes!$F$2:$F$3783, "code introuvable") -> non publié
A5: =Communes_HDF!A5 -> 02004 | B5: =Communes_HDF!B5 -> Agnicourt-et-Séchelles | C5: =_xlfn.XLOOKUP(A5, INSEE_Communes!$A$2:$A$3783, INSEE_Communes!$F$2:$F$3783, "code introuvable") -> non publié
A6: =Communes_HDF!A6 -> 02005 | B6: =Communes_HDF!B6 -> Aguilcourt | C6: =_xlfn.XLOOKUP(A6, INSEE_Communes!$A$2:$A$3783, INSEE_Communes!$F$2:$F$3783, "code introuvable") -> non publié | H6: =COUNTA(Jointure!A2:A3783) -> 3782
A7: =Communes_HDF!A7 -> 02006 | B7: =Communes_HDF!B7 -> Aisonville-et-Bernoville | C7: =_xlfn.XLOOKUP(A7, INSEE_Communes!$A$2:$A$3783, INSEE_Communes!$F$2:$F$3783, "code introuvable") -> non publié | H7: =COUNTIF(Jointure!C2:C3783, "code introuvable") -> 0
A8: =Communes_HDF!A8 -> 02007 | B8: =Communes_HDF!B8 -> Aizelles | C8: =_xlfn.XLOOKUP(A8, INSEE_Communes!$A$2:$A$3783, INSEE_Communes!$F$2:$F$3783, "code introuvable") -> non publié | H8: =COUNTIF(Jointure!C2:C3783, "non publié") -> 3262
A9: =Communes_HDF!A9 -> 02008 | B9: =Communes_HDF!B9 -> Aizy-Jouy | C9: =_xlfn.XLOOKUP(A9, INSEE_Communes!$A$2:$A$3783, INSEE_Communes!$F$2:$F$3783, "code introuvable") -> non publié
A10: =Communes_HDF!A10 -> 02009 | B10: =Communes_HDF!B10 -> Alaincourt | C10: =_xlfn.XLOOKUP(A10, INSEE_Communes!$A$2:$A$3783, INSEE_Communes!$F$2:$F$3783, "code introuvable") -> non publié
A11: =Communes_HDF!A11 -> 02010 | B11: =Communes_HDF!B11 -> Allemant | C11: =_xlfn.XLOOKUP(A11, INSEE_Communes!$A$2:$A$3783, INSEE_Communes!$F$2:$F$3783, "code introuvable") -> non publié
A12: =Communes_HDF!A12 -> 02011 | B12: =Communes_HDF!B12 -> Ambleny | C12: =_xlfn.XLOOKUP(A12, INSEE_Communes!$A$2:$A$3783, INSEE_Communes!$F$2:$F$3783, "code introuvable") -> non publié
A13: =Communes_HDF!A13 -> 02012 | B13: =Communes_HDF!B13 -> Ambrief | C13: =_xlfn.XLOOKUP(A13, INSEE_Communes!$A$2:$A$3783, INSEE_Communes!$F$2:$F$3783, "code introuvable") -> non publié
A14: =Communes_HDF!A14 -> 02013 | B14: =Communes_HDF!B14 -> Amifontaine | C14: =_xlfn.XLOOKUP(A14, INSEE_Communes!$A$2:$A$3783, INSEE_Communes!$F$2:$F$3783, "code introuvable") -> non publié
A15: =Communes_HDF!A15 -> 02014 | B15: =Communes_HDF!B15 -> Amigny-Rouy | C15: =_xlfn.XLOOKUP(A15, INSEE_Communes!$A$2:$A$3783, INSEE_Communes!$F$2:$F$3783, "code introuvable") -> non publié
A16: =Communes_HDF!A16 -> 02015 | B16: =Communes_HDF!B16 -> Ancienville | C16: =_xlfn.XLOOKUP(A16, INSEE_Communes!$A$2:$A$3783, INSEE_Communes!$F$2:$F$3783, "code introuvable") -> non publié
A17: =Communes_HDF!A17 -> 02016 | B17: =Communes_HDF!B17 -> Andelain | C17: =_xlfn.XLOOKUP(A17, INSEE_Communes!$A$2:$A$3783, INSEE_Communes!$F$2:$F$3783, "code introuvable") -> non publié
A18: =Communes_HDF!A18 -> 02017 | B18: =Communes_HDF!B18 -> Anguilcourt-le-Sart | C18: =_xlfn.XLOOKUP(A18, INSEE_Communes!$A$2:$A$3783, INSEE_Communes!$F$2:$F$3783, "code introuvable") -> non publié
A19: =Communes_HDF!A19 -> 02018 | B19: =Communes_HDF!B19 -> Anizy-le-Grand | C19: =_xlfn.XLOOKUP(A19, INSEE_Communes!$A$2:$A$3783, INSEE_Communes!$F$2:$F$3783, "code introuvable") -> 16
A20: =Communes_HDF!A20 -> 02019 | B20: =Communes_HDF!B20 -> Annois | C20: =_xlfn.XLOOKUP(A20, INSEE_Communes!$A$2:$A$3783, INSEE_Communes!$F$2:$F$3783, "code introuvable") -> non publié
... A3783: =Communes_HDF!A3783 -> 80485 | B3783: =Communes_HDF!B3783 -> Ô-de-Selle | C3783: =_xlfn.XLOOKUP(A3783, INSEE_Communes!$A$2:$A$3783, INSEE_Communes!$F$2:$F$3783, "code introuvable") -> non publié

Sheet Methode
A2: 1 Contrôle des données à la réception
A3: Tester la qualité du dossier de données :
A4: NB.VIDE sur les feuiles INSEE EPCI et Communes_HDF et Marche_immobilier_2024
A5: INSEE_EPCI | B5: =COUNTBLANK(INSEE_EPCI!A2:'INSEE_EPCI'!F93) -> 0
A6: Communes_HDF | B6: =COUNTBLANK(Communes_HDF!A2:'Communes_HDF'!I3783) -> 0 | H6: Autrement : INSEE : source réputée, je fais confiance
A7: Marche_immobilier_2024 | B7: =COUNTBLANK(Marche_immobilier_2024!A3:'Marche_immobilier_2024'!G1813) -> 0
A9: Etape 2 - choisir la maille
A10: choisis entre A. les 92 intercommunalités (tous les indicateurs sont publiés) et B. les communes (plus fin, mais le taux de pauvreté manque pour 3 262 communes sur 3 782)
A11: Je choisis la maille de l'intercommunalités parce que 1. limitation software : je vais pas faire défiler les 3783 lignes trop souvent sur Excel, 2. ça n'a pas de sens de travailler sur une part si petite des données : 13,77% 3. respect du secret statistique | Y11: =3262 -> 3262 | Z11: 3783 | AA11: =(Z11-Y11)/Z11 -> 0.13772139
A13: Etape 3 - In : Onglet "analyse"
A16: Étape 6 — Choisir tes critères
A17: choisis deux indicateurs de décision parmi : taux de pauvreté, nombre de personnes pauvres, évolution de la population, niveau de vie médian. Explique en trois lignes pourquoi ces deux-là pour cette question.
B18: Rappel prb : Qui aider en priorité, et pourquoi ? -> désigner des territoires prioritaires et justifier ce choix
B19: je choisis :
C20: - taux de pauvreté | H20: -> va me donner la part de population des EPCI en détresse financière
C21: - valeures minimales de niveau de vie médian / EPCI | H21: -> va me donner une indication des EPCI où le niveau de vie est le moins bon // à défaut de pouvoir considérer la valeur minimale avec Q1 // Et je retiens le nombre max de candidats possibles (12 territoires max pour l'exercice)
B23: AInsi, KPI indiquant l'urgence de financements à l'échelle de la population, et à l'échelle des portefeuilles des familles (j'imagine que ce sont les infos contenues dans l'intitulé "niveau de vie", revenus/foyer/éventuellement une valeur immobilière)
B24: je rejette : nb de personnes pauvres ne rend pas compte de la part sur population / évolution de la population : beaucoup de valeurs négatives, peu d'évolution positive générale observée (max : 5,27%) - ne semble pas pertinent

Sheet Analyse
A1: Code_EPCI | B1: Nom_EPCI | C1: nombre de communes | D1: superficie | E1: Population 2023 | F1: Niveau de vie médian | G1: taux de pauvreté | H1: Evolution de la population | I1: nombre de personnes pauvres | J1: densité
A2: =INSEE_EPCI!A2 -> 248000531 | B2: =INSEE_EPCI!B2 -> CA Amiens Métropole | C2: =COUNTIF(Communes_HDF!E:E, Analyse!A2) -> 39 | D2: =SUMIF(Communes_HDF!E:E,Analyse!A2,Communes_HDF!G:G) -> 351.47 | E2: =_xlfn.XLOOKUP(A2, INSEE_EPCI!$A$2:$A$93, INSEE_EPCI!$D$2:$D$93, "oupsi") -> 184392 | F2: =_xlfn.XLOOKUP(A2, INSEE_EPCI!$A$2:$A$93, INSEE_EPCI!$E$2:$E$93, "oupsi") -> 23640 | G2: =_xlfn.XLOOKUP(A2, INSEE_EPCI!$A$2:$A$93, INSEE_EPCI!$F$2:$F$93, "oupsi") -> 23.5 | H2: =(INSEE_EPCI!D2-INSEE_EPCI!C2)/INSEE_EPCI!C2 -> 0.019777011 | I2: =G2*E2/100 -> 43332.12 | J2: =E2/D2 -> 524.63084
A3: =INSEE_EPCI!A3 -> 200071785 | B3: =INSEE_EPCI!B3 -> CA Chauny Tergnier La Fère | C3: =COUNTIF(Communes_HDF!E:E, Analyse!A3) -> 48 | D3: =SUMIF(Communes_HDF!E:E,Analyse!A3,Communes_HDF!G:G) -> 385.08 | E3: =_xlfn.XLOOKUP(A3, INSEE_EPCI!$A$2:$A$93, INSEE_EPCI!$D$2:$D$93, "oupsi") -> 54027 | F3: =_xlfn.XLOOKUP(A3, INSEE_EPCI!$A$2:$A$93, INSEE_EPCI!$E$2:$E$93, "oupsi") -> 22590 | G3: =_xlfn.XLOOKUP(A3, INSEE_EPCI!$A$2:$A$93, INSEE_EPCI!$F$2:$F$93, "oupsi") -> 21.6 | H3: =(INSEE_EPCI!D3-INSEE_EPCI!C3)/INSEE_EPCI!C3 -> -0.026014062 | I3: =G3*E3/100 -> 11669.832 | J3: =E3/D3 -> 140.30072
A4: =INSEE_EPCI!A4 -> 245901152 | B4: =INSEE_EPCI!B4 -> CA Coeur d'Ostrevent | C4: =COUNTIF(Communes_HDF!E:E, Analyse!A4) -> 20 | D4: =SUMIF(Communes_HDF!E:E,Analyse!A4,Communes_HDF!G:G) -> 138.3 | E4: =_xlfn.XLOOKUP(A4, INSEE_EPCI!$A$2:$A$93, INSEE_EPCI!$D$2:$D$93, "oupsi") -> 69764 | F4: =_xlfn.XLOOKUP(A4, INSEE_EPCI!$A$2:$A$93, INSEE_EPCI!$E$2:$E$93, "oupsi") -> 22340 | G4: =_xlfn.XLOOKUP(A4, INSEE_EPCI!$A$2:$A$93, INSEE_EPCI!$F$2:$F$93, "oupsi") -> 21.1 | H4: =(INSEE_EPCI!D4-INSEE_EPCI!C4)/INSEE_EPCI!C4 -> -0.016812999 | I4: =G4*E4/100 -> 14720.204 | J4: =E4/D4 -> 504.43962
A5: =INSEE_EPCI!A5 -> 200040947 | B5: =INSEE_EPCI!B5 -> CA Coeur de Flandre | C5: =COUNTIF(Communes_HDF!E:E, Analyse!A5) -> 50 | D5: =SUMIF(Communes_HDF!E:E,Analyse!A5,Communes_HDF!G:G) -> 633.92 | E5: =_xlfn.XLOOKUP(A5, INSEE_EPCI!$A$2:$A$93, INSEE_EPCI!$D$2:$D$93, "oupsi") -> 102743 | F5: =_xlfn.XLOOKUP(A5, INSEE_EPCI!$A$2:$A$93, INSEE_EPCI!$E$2:$E$93, "oupsi") -> 25990 | G5: =_xlfn.XLOOKUP(A5, INSEE_EPCI!$A$2:$A$93, INSEE_EPCI!$F$2:$F$93, "oupsi") -> 11.1 | H5: =(INSEE_EPCI!D5-INSEE_EPCI!C5)/INSEE_EPCI!C5 -> 0.0046053661 | I5: =G5*E5/100 -> 11404.473 | J5: =E5/D5 -> 162.07566
A6: =INSEE_EPCI!A6 -> 200068047 | B6: =INSEE_EPCI!B6 -> CA Creil Sud Oise | C6: =COUNTIF(Communes_HDF!E:E, Analyse!A6) -> 11 | D6: =SUMIF(Communes_HDF!E:E,Analyse!A6,Communes_HDF!G:G) -> 83.61 | E6: =_xlfn.XLOOKUP(A6, INSEE_EPCI!$A$2:$A$93, INSEE_EPCI!$D$2:$D$93, "oupsi") -> 90234 | F6: =_xlfn.XLOOKUP(A6, INSEE_EPCI!$A$2:$A$93, INSEE_EPCI!$E$2:$E$93, "oupsi") -> 19250 | G6: =_xlfn.XLOOKUP(A6, INSEE_EPCI!$A$2:$A$93, INSEE_EPCI!$F$2:$F$93, "oupsi") -> 33.5 | H6: =(INSEE_EPCI!D6-INSEE_EPCI!C6)/INSEE_EPCI!C6 -> 0.043022933 | I6: =G6*E6/100 -> 30228.39 | J6: =E6/D6 -> 1079.225
A7: =INSEE_EPCI!A7 -> 200044618 | B7: =INSEE_EPCI!B7 -> CA Douaisis Agglo | C7: =COUNTIF(Communes_HDF!E:E, Analyse!A7) -> 35 | D7: =SUMIF(Communes_HDF!E:E,Analyse!A7,Communes_HDF!G:G) -> 235.58 | E7: =_xlfn.XLOOKUP(A7, INSEE_EPCI!$A$2:$A$93, INSEE_EPCI!$D$2:$D$93, "oupsi") -> 149282 | F7: =_xlfn.XLOOKUP(A7, INSEE_EPCI!$A$2:$A$93, INSEE_EPCI!$E$2:$E$93, "oupsi") -> 22540 | G7: =_xlfn.XLOOKUP(A7, INSEE_EPCI!$A$2:$A$93, INSEE_EPCI!$F$2:$F$93, "oupsi") -> 22.4 | H7: =(INSEE_EPCI!D7-INSEE_EPCI!C7)/INSEE_EPCI!C7 -> 0.0001607954 | I7: =G7*E7/100 -> 33439.168 | J7: =E7/D7 -> 633.67858
A8: =INSEE_EPCI!A8 -> 200090751 | B8: =INSEE_EPCI!B8 -> CA Grand Calais Terres et Mers | C8: =COUNTIF(Communes_HDF!E:E, Analyse!A8) -> 14 | D8: =SUMIF(Communes_HDF!E:E,Analyse!A8,Communes_HDF!G:G) -> 188.92 | E8: =_xlfn.XLOOKUP(A8, INSEE_EPCI!$A$2:$A$93, INSEE_EPCI!$D$2:$D$93, "oupsi") -> 98895 | F8: =_xlfn.XLOOKUP(A8, INSEE_EPCI!$A$2:$A$93, INSEE_EPCI!$E$2:$E$93, "oupsi") -> 22150 | G8: =_xlfn.XLOOKUP(A8, INSEE_EPCI!$A$2:$A$93, INSEE_EPCI!$F$2:$F$93, "oupsi") -> 23 | H8: =(INSEE_EPCI!D8-INSEE_EPCI!C8)/INSEE_EPCI!C8 -> -0.060549639 | I8: =G8*E8/100 -> 22745.85 | J8: =E8/D8 -> 523.47555
A9: =INSEE_EPCI!A9 -> 240200477 | B9: =INSEE_EPCI!B9 -> CA GrandSoissons Agglomération | C9: =COUNTIF(Communes_HDF!E:E, Analyse!A9) -> 27 | D9: =SUMIF(Communes_HDF!E:E,Analyse!A9,Communes_HDF!G:G) -> 181 | E9: =_xlfn.XLOOKUP(A9, INSEE_EPCI!$A$2:$A$93, INSEE_EPCI!$D$2:$D$93, "oupsi") -> 51809 | F9: =_xlfn.XLOOKUP(A9, INSEE_EPCI!$A$2:$A$93, INSEE_EPCI!$E$2:$E$93, "oupsi") -> 22560 | G9: =_xlfn.XLOOKUP(A9, INSEE_EPCI!$A$2:$A$93, INSEE_EPCI!$F$2:$F$93, "oupsi") -> 23.9 | H9: =(INSEE_EPCI!D9-INSEE_EPCI!C9)/INSEE_EPCI!C9 -> -0.0099182082 | I9: =G9*E9/100 -> 12382.351 | J9: =E9/D9 -> 286.23757
A10: =INSEE_EPCI!A10 -> 200043396 | B10: =INSEE_EPCI!B10 -> CA Maubeuge Val de Sambre | C10: =COUNTIF(Communes_HDF!E:E, Analyse!A10) -> 43 | D10: =SUMIF(Communes_HDF!E:E,Analyse!A10,Communes_HDF!G:G) -> 344.38 | E10: =_xlfn.XLOOKUP(A10, INSEE_EPCI!$A$2:$A$93, INSEE_EPCI!$D$2:$D$93, "oupsi") -> 122247 | F10: =_xlfn.XLOOKUP(A10, INSEE_EPCI!$A$2:$A$93, INSEE_EPCI!$E$2:$E$93, "oupsi") -> 20580 | G10: =_xlfn.XLOOKUP(A10, INSEE_EPCI!$A$2:$A$93, INSEE_EPCI!$F$2:$F$93, "oupsi") -> 28.6 | H10: =(INSEE_EPCI!D10-INSEE_EPCI!C10)/INSEE_EPCI!C10 -> -0.027090911 | I10: =G10*E10/100 -> 34962.642 | J10: =E10/D10 -> 354.97706
A11: =INSEE_EPCI!A11 -> 245901160 | B11: =INSEE_EPCI!B11 -> CA Valenciennes Métropole | C11: =COUNTIF(Communes_HDF!E:E, Analyse!A11) -> 35 | D11: =SUMIF(Communes_HDF!E:E,Analyse!A11,Communes_HDF!G:G) -> 262.85 | E11: =_xlfn.XLOOKUP(A11, INSEE_EPCI!$A$2:$A$93, INSEE_EPCI!$D$2:$D$93, "oupsi") -> 191738 | F11: =_xlfn.XLOOKUP(A11, INSEE_EPCI!$A$2:$A$93, INSEE_EPCI!$E$2:$E$93, "oupsi") -> 22000 | G11: =_xlfn.XLOOKUP(A11, INSEE_EPCI!$A$2:$A$93, INSEE_EPCI!$F$2:$F$93, "oupsi") -> 25 | H11: =(INSEE_EPCI!D11-INSEE_EPCI!C11)/INSEE_EPCI!C11 -> -0.0044445829 | I11: =G11*E11/100 -> 47934.5 | J11: =E11/D11 -> 729.45787
A12: =INSEE_EPCI!A12 -> 246200299 | B12: =INSEE_EPCI!B12 -> CA d'Hénin-Carvin | C12: =COUNTIF(Communes_HDF!E:E, Analyse!A12) -> 14 | D12: =SUMIF(Communes_HDF!E:E,Analyse!A12,Communes_HDF!G:G) -> 111.99 | E12: =_xlfn.XLOOKUP(A12, INSEE_EPCI!$A$2:$A$93, INSEE_EPCI!$D$2:$D$93, "oupsi") -> 125793 | F12: =_xlfn.XLOOKUP(A12, INSEE_EPCI!$A$2:$A$93, INSEE_EPCI!$E$2:$E$93, "oupsi") -> 21790 | G12: =_xlfn.XLOOKUP(A12, INSEE_EPCI!$A$2:$A$93, INSEE_EPCI!$F$2:$F$93, "oupsi") -> 23.3 | H12: =(INSEE_EPCI!D12-INSEE_EPCI!C12)/INSEE_EPCI!C12 -> -0.00033377041 | I12: =G12*E12/100 -> 29309.769 | J12: =E12/D12 -> 1123.2521
A13: =INSEE_EPCI!A13 -> 200072460 | B13: =INSEE_EPCI!B13 -> CA de Béthune-Bruay, Artois-Lys Romane | C13: =COUNTIF(Communes_HDF!E:E, Analyse!A13) -> 100 | D13: =SUMIF(Communes_HDF!E:E,Analyse!A13,Communes_HDF!G:G) -> 646.3 | E13: =_xlfn.XLOOKUP(A13, INSEE_EPCI!$A$2:$A$93, INSEE_EPCI!$D$2:$D$93, "oupsi") -> 275028 | F13: =_xlfn.XLOOKUP(A13, INSEE_EPCI!$A$2:$A$93, INSEE_EPCI!$E$2:$E$93, "oupsi") -> 22990 | G13: =_xlfn.XLOOKUP(A13, INSEE_EPCI!$A$2:$A$93, INSEE_EPCI!$F$2:$F$93, "oupsi") -> 19.4 | H13: =(INSEE_EPCI!D13-INSEE_EPCI!C13)/INSEE_EPCI!C13 -> -0.0067426281 | I13: =G13*E13/100 -> 53355.432 | J13: =E13/D13 -> 425.54232
... A93: =INSEE_EPCI!A93 -> 200093201 | B93: =INSEE_EPCI!B93 -> Métropole Européenne de Lille | C93: =COUNTIF(Communes_HDF!E:E, Analyse!A93) -> 95 | D93: =SUMIF(Communes_HDF!E:E,Analyse!A93,Communes_HDF!G:G) -> 672.78 | E93: =_xlfn.XLOOKUP(A93, INSEE_EPCI!$A$2:$A$93, INSEE_EPCI!$D$2:$D$93, "oupsi") -> 1195234 | F93: =_xlfn.XLOOKUP(A93, INSEE_EPCI!$A$2:$A$93, INSEE_EPCI!$E$2:$E$93, "oupsi") -> 24430 | G93: =_xlfn.XLOOKUP(A93, INSEE_EPCI!$A$2:$A$93, INSEE_EPCI!$F$2:$F$93, "oupsi") -> 21.4 | H93: =(INSEE_EPCI!D93-INSEE_EPCI!C93)/INSEE_EPCI!C93 -> 0.021017743 | I93: =G93*E93/100 -> 255780.08 | J93: =E93/D93 -> 1776.5599
H99: =MAX(H2:H93) -> 0.052746975

Sheet Feuil1
A4: EPCI | B4: Somme de Population
A5: CA Amiens Métropole | B5: 184392 | C5: =_xlfn.XLOOKUP(A5,INSEE_EPCI!$B$2:$B$93,INSEE_EPCI!$D$2:$D$93) -> 184392 | E5: =C5-B5 -> 0
A6: CA Chauny Tergnier La Fère | B6: 54027 | C6: =_xlfn.XLOOKUP(A6,INSEE_EPCI!$B$2:$B$93,INSEE_EPCI!$D$2:$D$93) -> 54027 | E6: =C6-B6 -> 0
A7: CA Coeur de Flandre | B7: 102743 | C7: =_xlfn.XLOOKUP(A7,INSEE_EPCI!$B$2:$B$93,INSEE_EPCI!$D$2:$D$93) -> 102743 | E7: =C7-B7 -> 0
A8: CA Coeur d'Ostrevent | B8: 69764 | C8: =_xlfn.XLOOKUP(A8,INSEE_EPCI!$B$2:$B$93,INSEE_EPCI!$D$2:$D$93) -> 69764 | E8: =C8-B8 -> 0
A9: CA Creil Sud Oise | B9: 90234 | C9: =_xlfn.XLOOKUP(A9,INSEE_EPCI!$B$2:$B$93,INSEE_EPCI!$D$2:$D$93) -> 90234 | E9: =C9-B9 -> 0
A10: CA de Béthune-Bruay, Artois-Lys Romane | B10: 275028 | C10: =_xlfn.XLOOKUP(A10,INSEE_EPCI!$B$2:$B$93,INSEE_EPCI!$D$2:$D$93) -> 275028 | E10: =C10-B10 -> 0
A11: CA de Cambrai | B11: 80120 | C11: =_xlfn.XLOOKUP(A11,INSEE_EPCI!$B$2:$B$93,INSEE_EPCI!$D$2:$D$93) -> 80120 | E11: =C11-B11 -> 0
A12: CA de la Baie de Somme | B12: 47572 | C12: =_xlfn.XLOOKUP(A12,INSEE_EPCI!$B$2:$B$93,INSEE_EPCI!$D$2:$D$93) -> 47572 | E12: =C12-B12 -> 0
A13: CA de la Porte du Hainaut | B13: 158419 | C13: =_xlfn.XLOOKUP(A13,INSEE_EPCI!$B$2:$B$93,INSEE_EPCI!$D$2:$D$93) -> 158419 | E13: =C13-B13 -> 0
A14: CA de la Région de Château-Thierry | B14: 54040 | C14: =_xlfn.XLOOKUP(A14,INSEE_EPCI!$B$2:$B$93,INSEE_EPCI!$D$2:$D$93) -> 54040 | E14: =C14-B14 -> 0
A15: CA de la Région de Compiègne et de la Basse Automne | B15: 83992 | C15: =_xlfn.XLOOKUP(A15,INSEE_EPCI!$B$2:$B$93,INSEE_EPCI!$D$2:$D$93) -> 83992 | E15: =C15-B15 -> 0
A16: CA de Lens - Liévin | B16: 242013 | C16: =_xlfn.XLOOKUP(A16,INSEE_EPCI!$B$2:$B$93,INSEE_EPCI!$D$2:$D$93) -> 242013 | E16: =C16-B16 -> 0
... A96: Métropole Européenne de Lille | B96: 1195234 | C96: =_xlfn.XLOOKUP(A96,INSEE_EPCI!$B$2:$B$93,INSEE_EPCI!$D$2:$D$93) -> 1195234 | E96: =C96-B96 -> 0
A97: Total général | B97: 5992194

Sheet Indicateurs
A1: Etape 4 - Position et dispersion
B3: Minimum | C3: Q1 | D3: médiane | E3: Q3 | F3: maximum | G3: moyenne simple | H3: moyenne pondérée par la population
A4: Taux de pauvreté | B4: =MIN(Analyse!G2:G93) -> 7 | C4: =_xlfn.QUARTILE.INC(Analyse!G2:G93,1) -> 12 | D4: =MEDIAN(Analyse!G2:G93) -> 14.5 | E4: =_xlfn.QUARTILE.INC(Analyse!G2:G93,3) -> 20.15 | F4: =MAX(Analyse!G2:G93) -> 33.5 | G4: =AVERAGE(Analyse!G2:G93) -> 16.086957 | H4: =SUMPRODUCT(Analyse!G2:G93,Analyse!E2:E93)/ SUM(Analyse!E2:E93) -> 19.063895
A5: Niveau de vie | B5: =MIN(Analyse!F2:F93) -> 19250 | C5: =_xlfn.QUARTILE.INC(Analyse!F2:F93,1) -> 23147.5 | D5: =MEDIAN(Analyse!F2:F93) -> 24350 | E5: =_xlfn.QUARTILE.INC(Analyse!F2:F93,3) -> 25687.5 | F5: =MAX(Analyse!F2:F93) -> 34810 | G5: =AVERAGE(Analyse!F2:F93) -> 24483.152 | H5: =SUMPRODUCT(Analyse!F2:F93,Analyse!E2:E93)/ SUM(Analyse!E2:E93) -> 23978.569
A7: Minimum | B7: le minimum de pauvreté par EPCI de la région est 7 (CC de la plaine d'Estrées)
A8: Q1 | B8: le premier quartile de taux de pauvreté par EPCI de la région est de 12
A9: Mediane | B9: la médiane des taux de pauvreté par EPCI de la région est de 14,5
A10: Q3 | B10: Le troisième quartile des taux de pauvreté par EPCI de la région est de 20,5
A11: Maximum | B11: Le taux de pauvreté maximum par EPCI de la région est 33,5
A12: Moyenne simple | B12: la moyenne simple de taux de pauvreté par EPCI de la région est de 16,1 (arrondi)
A13: Moyenne pondérée par la population | B13: La moyenne pondérée par la population, de taux de pauvreté par EPCI de la région est 19,1 (arrondi)
A15: Etape 5 - Ce qui manque
A17: Combien de communes sans taux de pauvreté publié ? | D17: =COUNTIF(INSEE_Communes!F2:F3783, "non publié") -> 3262
A18: Combien d'habitants y vivent ? | D18: =SUMIFS(INSEE_Communes!C2:C3783, INSEE_Communes!F2:F3783, "non publié") -> 1668752
A19: Deux intercommunalités débordent sur la Normandie : lesquelles, et qu'est-ce que ça change ? | F19: pour les trouver : onglet Feuil1, tableau croisé dynamique sur copie de Communes_HDF, somme de population par EPCI / comparé à somme de population EPCI de la feuille INSEE_EPCI, soustraction des deux colones pour mettre les deux entrées différentes en évidence
B21: somme pop Communes_HDF | C21: somme pop INSEE EPCI | D21: différence
A22: CC des Villes Soeurs | B22: 13674 | C22: =_xlfn.XLOOKUP(Feuil1!A52,INSEE_EPCI!$B$2:$B$93,INSEE_EPCI!$D$2:$D$93) -> 35390 | D22: =(C22-B22)/B22 -> 1.5881234
A23: CC Interrégionale Aumale - Blangy-sur-Bresle | B23: 4261 | C23: =_xlfn.XLOOKUP(Feuil1!A81,INSEE_EPCI!$B$2:$B$93,INSEE_EPCI!$D$2:$D$93) -> 21154 | D23: =(C23-B23)/B23 -> 3.9645623

Sheet Décision
A1: Étape 7 — La règle
A2: taux de pauvreté et valeurs minimales du niveau de vie médian
A3: Liste : CA Creil Sud Oise, CC du Sud Avesnois, Ca Maubeuge Val de Sambre, CC des Trois Rivières, CA de Lens - Liévin, CA Valenciennes métropole, CC des Portes de la Thiérache, CC Thiérache Sambre et Oise, CA du Saint-Quentinois, CA GrandSoissons Agglomération, CA de la Porte du Hainaut, CA Amiens Métropole
A5: Code_EPCI | B5: Nom_EPCI | C5: taux de pauvreté | D5: Niveau de vie médian | E5: nombre de communes | F5: superficie | G5: Population 2023 | H5: Evolution de la population | I5: nombre de personnes pauvres | J5: densité
A6: =INSEE_EPCI!A6 -> 200068047 | B6: =INSEE_EPCI!B6 -> CA Creil Sud Oise | C6: =_xlfn.XLOOKUP(A6, INSEE_EPCI!$A$2:$A$93, INSEE_EPCI!$F$2:$F$93, "oupsi") -> 33.5 | D6: =_xlfn.XLOOKUP(A6, INSEE_EPCI!$A$2:$A$93, INSEE_EPCI!$E$2:$E$93, "oupsi") -> 19250 | E6: =COUNTIF(Communes_HDF!E:E, Décision!A10) -> 36 | F6: =SUMIF(Communes_HDF!E:E,Décision!A10,Communes_HDF!G:G) -> 239.58 | G6: =_xlfn.XLOOKUP(A6, INSEE_EPCI!$A$2:$A$93, INSEE_EPCI!$D$2:$D$93, "oupsi") -> 90234 | H6: =(INSEE_EPCI!D6-INSEE_EPCI!C6)/INSEE_EPCI!C6 -> 0.043022933 | I6: =C6*G6/100 -> 30228.39 | J6: =G6/F6 -> 376.63411
A7: =INSEE_EPCI!A83 -> 200043404 | B7: =INSEE_EPCI!B83 -> CC du Sud Avesnois | C7: =_xlfn.XLOOKUP(A7, INSEE_EPCI!$A$2:$A$93, INSEE_EPCI!$F$2:$F$93, "oupsi") -> 29.7 | D7: =_xlfn.XLOOKUP(A7, INSEE_EPCI!$A$2:$A$93, INSEE_EPCI!$E$2:$E$93, "oupsi") -> 20100 | E7: =COUNTIF(Communes_HDF!E:E, Décision!A87) -> 26 | F7: =SUMIF(Communes_HDF!E:E,Décision!A87,Communes_HDF!G:G) -> 232.1 | G7: =_xlfn.XLOOKUP(A7, INSEE_EPCI!$A$2:$A$93, INSEE_EPCI!$D$2:$D$93, "oupsi") -> 24208 | H7: =(INSEE_EPCI!D83-INSEE_EPCI!C83)/INSEE_EPCI!C83 -> -0.039593748 | I7: =C7*G7/100 -> 7189.776 | J7: =G7/F7 -> 104.29987
A8: =INSEE_EPCI!A10 -> 200043396 | B8: =INSEE_EPCI!B10 -> CA Maubeuge Val de Sambre | C8: =_xlfn.XLOOKUP(A8, INSEE_EPCI!$A$2:$A$93, INSEE_EPCI!$F$2:$F$93, "oupsi") -> 28.6 | D8: =_xlfn.XLOOKUP(A8, INSEE_EPCI!$A$2:$A$93, INSEE_EPCI!$E$2:$E$93, "oupsi") -> 20580 | E8: =COUNTIF(Communes_HDF!E:E, Décision!A14) -> 39 | F8: =SUMIF(Communes_HDF!E:E,Décision!A14,Communes_HDF!G:G) -> 294.8 | G8: =_xlfn.XLOOKUP(A8, INSEE_EPCI!$A$2:$A$93, INSEE_EPCI!$D$2:$D$93, "oupsi") -> 122247 | H8: =(INSEE_EPCI!D10-INSEE_EPCI!C10)/INSEE_EPCI!C10 -> -0.027090911 | I8: =C8*G8/100 -> 34962.642 | J8: =G8/F8 -> 414.67775
A9: =INSEE_EPCI!A62 -> 240200600 | B9: =INSEE_EPCI!B62 -> CC des Trois Rivières | C9: =_xlfn.XLOOKUP(A9, INSEE_EPCI!$A$2:$A$93, INSEE_EPCI!$F$2:$F$93, "oupsi") -> 26 | D9: =_xlfn.XLOOKUP(A9, INSEE_EPCI!$A$2:$A$93, INSEE_EPCI!$E$2:$E$93, "oupsi") -> 20630 | E9: =COUNTIF(Communes_HDF!E:E, Décision!A66) -> 54 | F9: =SUMIF(Communes_HDF!E:E,Décision!A66,Communes_HDF!G:G) -> 537.2 | G9: =_xlfn.XLOOKUP(A9, INSEE_EPCI!$A$2:$A$93, INSEE_EPCI!$D$2:$D$93, "oupsi") -> 20346 | H9: =(INSEE_EPCI!D62-INSEE_EPCI!C62)/INSEE_EPCI!C62 -> -0.043486437 | I9: =C9*G9/100 -> 5289.96 | J9: =G9/F9 -> 37.874162
A10: =INSEE_EPCI!A15 -> 246200364 | B10: =INSEE_EPCI!B15 -> CA de Lens - Liévin | C10: =_xlfn.XLOOKUP(A10, INSEE_EPCI!$A$2:$A$93, INSEE_EPCI!$F$2:$F$93, "oupsi") -> 25.3 | D10: =_xlfn.XLOOKUP(A10, INSEE_EPCI!$A$2:$A$93, INSEE_EPCI!$E$2:$E$93, "oupsi") -> 21190 | E10: =COUNTIF(Communes_HDF!E:E, Décision!A19) -> 14 | F10: =SUMIF(Communes_HDF!E:E,Décision!A19,Communes_HDF!G:G) -> 188.92 | G10: =_xlfn.XLOOKUP(A10, INSEE_EPCI!$A$2:$A$93, INSEE_EPCI!$D$2:$D$93, "oupsi") -> 242013 | H10: =(INSEE_EPCI!D15-INSEE_EPCI!C15)/INSEE_EPCI!C15 -> 0.00032653534 | I10: =C10*G10/100 -> 61229.289 | J10: =G10/F10 -> 1281.0343
A11: =INSEE_EPCI!A11 -> 245901160 | B11: =INSEE_EPCI!B11 -> CA Valenciennes Métropole | C11: =_xlfn.XLOOKUP(A11, INSEE_EPCI!$A$2:$A$93, INSEE_EPCI!$F$2:$F$93, "oupsi") -> 25 | D11: =_xlfn.XLOOKUP(A11, INSEE_EPCI!$A$2:$A$93, INSEE_EPCI!$E$2:$E$93, "oupsi") -> 22000 | E11: =COUNTIF(Communes_HDF!E:E, Décision!A15) -> 27 | F11: =SUMIF(Communes_HDF!E:E,Décision!A15,Communes_HDF!G:G) -> 181 | G11: =_xlfn.XLOOKUP(A11, INSEE_EPCI!$A$2:$A$93, INSEE_EPCI!$D$2:$D$93, "oupsi") -> 191738 | H11: =(INSEE_EPCI!D11-INSEE_EPCI!C11)/INSEE_EPCI!C11 -> -0.0044445829 | I11: =C11*G11/100 -> 47934.5 | J11: =G11/F11 -> 1059.326
A12: =INSEE_EPCI!A60 -> 240200634 | B12: =INSEE_EPCI!B60 -> CC des Portes de la Thiérache | C12: =_xlfn.XLOOKUP(A12, INSEE_EPCI!$A$2:$A$93, INSEE_EPCI!$F$2:$F$93, "oupsi") -> 24 | D12: =_xlfn.XLOOKUP(A12, INSEE_EPCI!$A$2:$A$93, INSEE_EPCI!$E$2:$E$93, "oupsi") -> 21250 | E12: =COUNTIF(Communes_HDF!E:E, Décision!A64) -> 52 | F12: =SUMIF(Communes_HDF!E:E,Décision!A64,Communes_HDF!G:G) -> 397.27 | G12: =_xlfn.XLOOKUP(A12, INSEE_EPCI!$A$2:$A$93, INSEE_EPCI!$D$2:$D$93, "oupsi") -> 6622 | H12: =(INSEE_EPCI!D60-INSEE_EPCI!C60)/INSEE_EPCI!C60 -> -0.053864838 | I12: =C12*G12/100 -> 1589.28 | J12: =G12/F12 -> 16.668764
A13: =INSEE_EPCI!A42 -> 200071983 | B13: =INSEE_EPCI!B42 -> CC Thiérache Sambre et Oise | C13: =_xlfn.XLOOKUP(A13, INSEE_EPCI!$A$2:$A$93, INSEE_EPCI!$F$2:$F$93, "oupsi") -> 24 | D13: =_xlfn.XLOOKUP(A13, INSEE_EPCI!$A$2:$A$93, INSEE_EPCI!$E$2:$E$93, "oupsi") -> 21700 | E13: =COUNTIF(Communes_HDF!E:E, Décision!A46) -> 43 | F13: =SUMIF(Communes_HDF!E:E,Décision!A46,Communes_HDF!G:G) -> 297.82 | G13: =_xlfn.XLOOKUP(A13, INSEE_EPCI!$A$2:$A$93, INSEE_EPCI!$D$2:$D$93, "oupsi") -> 16257 | H13: =(INSEE_EPCI!D42-INSEE_EPCI!C42)/INSEE_EPCI!C42 -> -0.039354724 | I13: =C13*G13/100 -> 3901.68 | J13: =G13/F13 -> 54.586663
A14: =INSEE_EPCI!A26 -> 200071892 | B14: =INSEE_EPCI!B26 -> CA du Saint-Quentinois | C14: =_xlfn.XLOOKUP(A14, INSEE_EPCI!$A$2:$A$93, INSEE_EPCI!$F$2:$F$93, "oupsi") -> 24 | D14: =_xlfn.XLOOKUP(A14, INSEE_EPCI!$A$2:$A$93, INSEE_EPCI!$E$2:$E$93, "oupsi") -> 22260 | E14: =COUNTIF(Communes_HDF!E:E, Décision!A30) -> 100 | F14: =SUMIF(Communes_HDF!E:E,Décision!A30,Communes_HDF!G:G) -> 646.3 | G14: =_xlfn.XLOOKUP(A14, INSEE_EPCI!$A$2:$A$93, INSEE_EPCI!$D$2:$D$93, "oupsi") -> 79010 | H14: =(INSEE_EPCI!D26-INSEE_EPCI!C26)/INSEE_EPCI!C26 -> -0.021923472 | I14: =C14*G14/100 -> 18962.4 | J14: =G14/F14 -> 122.24973
A15: =INSEE_EPCI!A9 -> 240200477 | B15: =INSEE_EPCI!B9 -> CA GrandSoissons Agglomération | C15: =_xlfn.XLOOKUP(A15, INSEE_EPCI!$A$2:$A$93, INSEE_EPCI!$F$2:$F$93, "oupsi") -> 23.9 | D15: =_xlfn.XLOOKUP(A15, INSEE_EPCI!$A$2:$A$93, INSEE_EPCI!$E$2:$E$93, "oupsi") -> 22560 | E15: =COUNTIF(Communes_HDF!E:E, Décision!A13) -> 36 | F15: =SUMIF(Communes_HDF!E:E,Décision!A13,Communes_HDF!G:G) -> 331.98 | G15: =_xlfn.XLOOKUP(A15, INSEE_EPCI!$A$2:$A$93, INSEE_EPCI!$D$2:$D$93, "oupsi") -> 51809 | H15: =(INSEE_EPCI!D9-INSEE_EPCI!C9)/INSEE_EPCI!C9 -> -0.0099182082 | I15: =C15*G15/100 -> 12382.351 | J15: =G15/F15 -> 156.06061
A16: =INSEE_EPCI!A17 -> 200042190 | B16: =INSEE_EPCI!B17 -> CA de la Porte du Hainaut | C16: =_xlfn.XLOOKUP(A16, INSEE_EPCI!$A$2:$A$93, INSEE_EPCI!$F$2:$F$93, "oupsi") -> 23.6 | D16: =_xlfn.XLOOKUP(A16, INSEE_EPCI!$A$2:$A$93, INSEE_EPCI!$E$2:$E$93, "oupsi") -> 21900 | E16: =COUNTIF(Communes_HDF!E:E, Décision!A21) -> 38 | F16: =SUMIF(Communes_HDF!E:E,Décision!A21,Communes_HDF!G:G) -> 318.06 | G16: =_xlfn.XLOOKUP(A16, INSEE_EPCI!$A$2:$A$93, INSEE_EPCI!$D$2:$D$93, "oupsi") -> 158419 | H16: =(INSEE_EPCI!D17-INSEE_EPCI!C17)/INSEE_EPCI!C17 -> -0.0021101831 | I16: =C16*G16/100 -> 37386.884 | J16: =G16/F16 -> 498.07898
A17: =INSEE_EPCI!A2 -> 248000531 | B17: =INSEE_EPCI!B2 -> CA Amiens Métropole | C17: =_xlfn.XLOOKUP(A17, INSEE_EPCI!$A$2:$A$93, INSEE_EPCI!$F$2:$F$93, "oupsi") -> 23.5 | D17: =_xlfn.XLOOKUP(A17, INSEE_EPCI!$A$2:$A$93, INSEE_EPCI!$E$2:$E$93, "oupsi") -> 23640 | E17: =COUNTIF(Communes_HDF!E:E, Décision!A6) -> 11 | F17: =SUMIF(Communes_HDF!E:E,Décision!A6,Communes_HDF!G:G) -> 83.61 | G17: =_xlfn.XLOOKUP(A17, INSEE_EPCI!$A$2:$A$93, INSEE_EPCI!$D$2:$D$93, "oupsi") -> 184392 | H17: =(INSEE_EPCI!D2-INSEE_EPCI!C2)/INSEE_EPCI!C2 -> 0.019777011 | I17: =C17*G17/100 -> 43332.12 | J17: =G17/F17 -> 2205.3821
A18: =INSEE_EPCI!A12 -> 246200299 | B18: =INSEE_EPCI!B12 -> CA d'Hénin-Carvin | C18: =_xlfn.XLOOKUP(A18, INSEE_EPCI!$A$2:$A$93, INSEE_EPCI!$F$2:$F$93, "oupsi") -> 23.3 | D18: =_xlfn.XLOOKUP(A18, INSEE_EPCI!$A$2:$A$93, INSEE_EPCI!$E$2:$E$93, "oupsi") -> 21790 | E18: =COUNTIF(Communes_HDF!E:E, Décision!A16) -> 47 | F18: =SUMIF(Communes_HDF!E:E,Décision!A16,Communes_HDF!G:G) -> 372.19 | G18: =_xlfn.XLOOKUP(A18, INSEE_EPCI!$A$2:$A$93, INSEE_EPCI!$D$2:$D$93, "oupsi") -> 125793 | H18: =(INSEE_EPCI!D12-INSEE_EPCI!C12)/INSEE_EPCI!C12 -> -0.00033377041 | I18: =C18*G18/100 -> 29309.769 | J18: =G18/F18 -> 337.9806
A19: =INSEE_EPCI!A8 -> 200090751 | B19: =INSEE_EPCI!B8 -> CA Grand Calais Terres et Mers | C19: =_xlfn.XLOOKUP(A19, INSEE_EPCI!$A$2:$A$93, INSEE_EPCI!$F$2:$F$93, "oupsi") -> 23 | D19: =_xlfn.XLOOKUP(A19, INSEE_EPCI!$A$2:$A$93, INSEE_EPCI!$E$2:$E$93, "oupsi") -> 22150 | E19: =COUNTIF(Communes_HDF!E:E, Décision!A12) -> 30 | F19: =SUMIF(Communes_HDF!E:E,Décision!A12,Communes_HDF!G:G) -> 258.11 | G19: =_xlfn.XLOOKUP(A19, INSEE_EPCI!$A$2:$A$93, INSEE_EPCI!$D$2:$D$93, "oupsi") -> 98895 | H19: =(INSEE_EPCI!D8-INSEE_EPCI!C8)/INSEE_EPCI!C8 -> -0.060549639 | I19: =C19*G19/100 -> 22745.85 | J19: =G19/F19 -> 383.15059
A20: =INSEE_EPCI!A7 -> 200044618 | B20: =INSEE_EPCI!B7 -> CA Douaisis Agglo | C20: =_xlfn.XLOOKUP(A20, INSEE_EPCI!$A$2:$A$93, INSEE_EPCI!$F$2:$F$93, "oupsi") -> 22.4 | D20: =_xlfn.XLOOKUP(A20, INSEE_EPCI!$A$2:$A$93, INSEE_EPCI!$E$2:$E$93, "oupsi") -> 22540 | E20: =COUNTIF(Communes_HDF!E:E, Décision!A11) -> 35 | F20: =SUMIF(Communes_HDF!E:E,Décision!A11,Communes_HDF!G:G) -> 262.85 | G20: =_xlfn.XLOOKUP(A20, INSEE_EPCI!$A$2:$A$93, INSEE_EPCI!$D$2:$D$93, "oupsi") -> 149282 | H20: =(INSEE_EPCI!D7-INSEE_EPCI!C7)/INSEE_EPCI!C7 -> 0.0001607954 | I20: =C20*G20/100 -> 33439.168 | J20: =G20/F20 -> 567.93609
A21: =INSEE_EPCI!A24 -> 200043495 | B21: =INSEE_EPCI!B24 -> CA du Pays de Laon | C21: =_xlfn.XLOOKUP(A21, INSEE_EPCI!$A$2:$A$93, INSEE_EPCI!$F$2:$F$93, "oupsi") -> 22.4 | D21: =_xlfn.XLOOKUP(A21, INSEE_EPCI!$A$2:$A$93, INSEE_EPCI!$E$2:$E$93, "oupsi") -> 23010 | E21: =COUNTIF(Communes_HDF!E:E, Décision!A28) -> 17 | F21: =SUMIF(Communes_HDF!E:E,Décision!A28,Communes_HDF!G:G) -> 300.98 | G21: =_xlfn.XLOOKUP(A21, INSEE_EPCI!$A$2:$A$93, INSEE_EPCI!$D$2:$D$93, "oupsi") -> 41835 | H21: =(INSEE_EPCI!D24-INSEE_EPCI!C24)/INSEE_EPCI!C24 -> -0.024461338 | I21: =C21*G21/100 -> 9371.04 | J21: =G21/F21 -> 138.99595
A22: =INSEE_EPCI!A23 -> 200030633 | B22: =INSEE_EPCI!B23 -> CA du Caudrésis et du Catésis | C22: =_xlfn.XLOOKUP(A22, INSEE_EPCI!$A$2:$A$93, INSEE_EPCI!$F$2:$F$93, "oupsi") -> 22.3 | D22: =_xlfn.XLOOKUP(A22, INSEE_EPCI!$A$2:$A$93, INSEE_EPCI!$E$2:$E$93, "oupsi") -> 21850 | E22: =COUNTIF(Communes_HDF!E:E, Décision!A27) -> 22 | F22: =SUMIF(Communes_HDF!E:E,Décision!A27,Communes_HDF!G:G) -> 205.28 | G22: =_xlfn.XLOOKUP(A22, INSEE_EPCI!$A$2:$A$93, INSEE_EPCI!$D$2:$D$93, "oupsi") -> 62870 | H22: =(INSEE_EPCI!D23-INSEE_EPCI!C23)/INSEE_EPCI!C23 -> -0.030397434 | I22: =C22*G22/100 -> 14020.01 | J22: =G22/F22 -> 306.26461
A23: =INSEE_EPCI!A3 -> 200071785 | B23: =INSEE_EPCI!B3 -> CA Chauny Tergnier La Fère | C23: =_xlfn.XLOOKUP(A23, INSEE_EPCI!$A$2:$A$93, INSEE_EPCI!$F$2:$F$93, "oupsi") -> 21.6 | D23: =_xlfn.XLOOKUP(A23, INSEE_EPCI!$A$2:$A$93, INSEE_EPCI!$E$2:$E$93, "oupsi") -> 22590 | E23: =COUNTIF(Communes_HDF!E:E, Décision!A7) -> 12 | F23: =SUMIF(Communes_HDF!E:E,Décision!A7,Communes_HDF!G:G) -> 179.04 | G23: =_xlfn.XLOOKUP(A23, INSEE_EPCI!$A$2:$A$93, INSEE_EPCI!$D$2:$D$93, "oupsi") -> 54027 | H23: =(INSEE_EPCI!D3-INSEE_EPCI!C3)/INSEE_EPCI!C3 -> -0.026014062 | I23: =C23*G23/100 -> 11669.832 | J23: =G23/F23 -> 301.75938
A24: =INSEE_EPCI!A93 -> 200093201 | B24: =INSEE_EPCI!B93 -> Métropole Européenne de Lille | C24: =_xlfn.XLOOKUP(A24, INSEE_EPCI!$A$2:$A$93, INSEE_EPCI!$F$2:$F$93, "oupsi") -> 21.4 | D24: =_xlfn.XLOOKUP(A24, INSEE_EPCI!$A$2:$A$93, INSEE_EPCI!$E$2:$E$93, "oupsi") -> 24430 | E24: =COUNTIF(Communes_HDF!E:E, Décision!A97) -> 37 | F24: =SUMIF(Communes_HDF!E:E,Décision!A97,Communes_HDF!G:G) -> 314.69 | G24: =_xlfn.XLOOKUP(A24, INSEE_EPCI!$A$2:$A$93, INSEE_EPCI!$D$2:$D$93, "oupsi") -> 1195234 | H24: =(INSEE_EPCI!D93-INSEE_EPCI!C93)/INSEE_EPCI!C93 -> 0.021017743 | I24: =C24*G24/100 -> 255780.08 | J24: =G24/F24 -> 3798.1315
A25: =INSEE_EPCI!A4 -> 245901152 | B25: =INSEE_EPCI!B4 -> CA Coeur d'Ostrevent | C25: =_xlfn.XLOOKUP(A25, INSEE_EPCI!$A$2:$A$93, INSEE_EPCI!$F$2:$F$93, "oupsi") -> 21.1 | D25: =_xlfn.XLOOKUP(A25, INSEE_EPCI!$A$2:$A$93, INSEE_EPCI!$E$2:$E$93, "oupsi") -> 22340 | E25: =COUNTIF(Communes_HDF!E:E, Décision!A8) -> 43 | F25: =SUMIF(Communes_HDF!E:E,Décision!A8,Communes_HDF!G:G) -> 344.38 | G25: =_xlfn.XLOOKUP(A25, INSEE_EPCI!$A$2:$A$93, INSEE_EPCI!$D$2:$D$93, "oupsi") -> 69764 | H25: =(INSEE_EPCI!D4-INSEE_EPCI!C4)/INSEE_EPCI!C4 -> -0.016812999 | I25: =C25*G25/100 -> 14720.204 | J25: =G25/F25 -> 202.57855
A26: =INSEE_EPCI!A28 -> 200043263 | B26: =INSEE_EPCI!B28 -> CC Coeur de l'Avesnois | C26: =_xlfn.XLOOKUP(A26, INSEE_EPCI!$A$2:$A$93, INSEE_EPCI!$F$2:$F$93, "oupsi") -> 20.9 | D26: =_xlfn.XLOOKUP(A26, INSEE_EPCI!$A$2:$A$93, INSEE_EPCI!$E$2:$E$93, "oupsi") -> 22920 | E26: =COUNTIF(Communes_HDF!E:E, Décision!A32) -> 53 | F26: =SUMIF(Communes_HDF!E:E,Décision!A32,Communes_HDF!G:G) -> 540.86 | G26: =_xlfn.XLOOKUP(A26, INSEE_EPCI!$A$2:$A$93, INSEE_EPCI!$D$2:$D$93, "oupsi") -> 28503 | H26: =(INSEE_EPCI!D28-INSEE_EPCI!C28)/INSEE_EPCI!C28 -> -0.054720923 | I26: =C26*G26/100 -> 5957.127 | J26: =G26/F26 -> 52.699405
A27: =INSEE_EPCI!A22 -> 246200729 | B27: =INSEE_EPCI!B22 -> CA du Boulonnais | C27: =_xlfn.XLOOKUP(A27, INSEE_EPCI!$A$2:$A$93, INSEE_EPCI!$F$2:$F$93, "oupsi") -> 20.6 | D27: =_xlfn.XLOOKUP(A27, INSEE_EPCI!$A$2:$A$93, INSEE_EPCI!$E$2:$E$93, "oupsi") -> 22740 | E27: =COUNTIF(Communes_HDF!E:E, Décision!A26) -> 43 | F27: =SUMIF(Communes_HDF!E:E,Décision!A26,Communes_HDF!G:G) -> 417.83 | G27: =_xlfn.XLOOKUP(A27, INSEE_EPCI!$A$2:$A$93, INSEE_EPCI!$D$2:$D$93, "oupsi") -> 111647 | H27: =(INSEE_EPCI!D22-INSEE_EPCI!C22)/INSEE_EPCI!C22 -> -0.013814912 | I27: =C27*G27/100 -> 22999.282 | J27: =G27/F27 -> 267.20676
A28: =INSEE_EPCI!A92 -> 245900428 | B28: =INSEE_EPCI!B92 -> CU de Dunkerque | C28: =_xlfn.XLOOKUP(A28, INSEE_EPCI!$A$2:$A$93, INSEE_EPCI!$F$2:$F$93, "oupsi") -> 20.3 | D28: =_xlfn.XLOOKUP(A28, INSEE_EPCI!$A$2:$A$93, INSEE_EPCI!$E$2:$E$93, "oupsi") -> 23270 | E28: =COUNTIF(Communes_HDF!E:E, Décision!A96) -> 19 | F28: =SUMIF(Communes_HDF!E:E,Décision!A96,Communes_HDF!G:G) -> 166.72 | G28: =_xlfn.XLOOKUP(A28, INSEE_EPCI!$A$2:$A$93, INSEE_EPCI!$D$2:$D$93, "oupsi") -> 191478 | H28: =(INSEE_EPCI!D92-INSEE_EPCI!C92)/INSEE_EPCI!C92 -> -0.02754176 | I28: =C28*G28/100 -> 38870.034 | J28: =G28/F28 -> 1148.5005
A29: =INSEE_EPCI!A71 -> 246000756 | B29: =INSEE_EPCI!B71 -> CC du Pays Noyonnais | C29: =_xlfn.XLOOKUP(A29, INSEE_EPCI!$A$2:$A$93, INSEE_EPCI!$F$2:$F$93, "oupsi") -> 20.1 | D29: =_xlfn.XLOOKUP(A29, INSEE_EPCI!$A$2:$A$93, INSEE_EPCI!$E$2:$E$93, "oupsi") -> 23240 | E29: =COUNTIF(Communes_HDF!E:E, Décision!A75) -> 23 | F29: =SUMIF(Communes_HDF!E:E,Décision!A75,Communes_HDF!G:G) -> 246.41 | G29: =_xlfn.XLOOKUP(A29, INSEE_EPCI!$A$2:$A$93, INSEE_EPCI!$D$2:$D$93, "oupsi") -> 31901 | H29: =(INSEE_EPCI!D71-INSEE_EPCI!C71)/INSEE_EPCI!C71 -> -0.0322473 | I29: =C29*G29/100 -> 6412.101 | J29: =G29/F29 -> 129.46309
A30: =INSEE_EPCI!A13 -> 200072460 | B30: =INSEE_EPCI!B13 -> CA de Béthune-Bruay, Artois-Lys Romane | C30: =_xlfn.XLOOKUP(A30, INSEE_EPCI!$A$2:$A$93, INSEE_EPCI!$F$2:$F$93, "oupsi") -> 19.4 | D30: =_xlfn.XLOOKUP(A30, INSEE_EPCI!$A$2:$A$93, INSEE_EPCI!$E$2:$E$93, "oupsi") -> 22990 | E30: =COUNTIF(Communes_HDF!E:E, Décision!A17) -> 39 | F30: =SUMIF(Communes_HDF!E:E,Décision!A17,Communes_HDF!G:G) -> 351.47 | G30: =_xlfn.XLOOKUP(A30, INSEE_EPCI!$A$2:$A$93, INSEE_EPCI!$D$2:$D$93, "oupsi") -> 275028 | H30: =(INSEE_EPCI!D13-INSEE_EPCI!C13)/INSEE_EPCI!C13 -> -0.0067426281 | I30: =C30*G30/100 -> 53355.432 | J30: =G30/F30 -> 782.50775
A31: =INSEE_EPCI!A53 -> 240200444 | B31: =INSEE_EPCI!B53 -> CC de la Thiérache du Centre | C31: =_xlfn.XLOOKUP(A31, INSEE_EPCI!$A$2:$A$93, INSEE_EPCI!$F$2:$F$93, "oupsi") -> 19.3 | D31: =_xlfn.XLOOKUP(A31, INSEE_EPCI!$A$2:$A$93, INSEE_EPCI!$E$2:$E$93, "oupsi") -> 22900 | E31: =COUNTIF(Communes_HDF!E:E, Décision!A57) -> 10 | F31: =SUMIF(Communes_HDF!E:E,Décision!A57,Communes_HDF!G:G) -> 86.45 | G31: =_xlfn.XLOOKUP(A31, INSEE_EPCI!$A$2:$A$93, INSEE_EPCI!$D$2:$D$93, "oupsi") -> 25590 | H31: =(INSEE_EPCI!D53-INSEE_EPCI!C53)/INSEE_EPCI!C53 -> -0.032441016 | I31: =C31*G31/100 -> 4938.87 | J31: =G31/F31 -> 296.00925
A32: =INSEE_EPCI!A21 -> 200067999 | B32: =INSEE_EPCI!B21 -> CA du Beauvaisis | C32: =_xlfn.XLOOKUP(A32, INSEE_EPCI!$A$2:$A$93, INSEE_EPCI!$F$2:$F$93, "oupsi") -> 19.2 | D32: =_xlfn.XLOOKUP(A32, INSEE_EPCI!$A$2:$A$93, INSEE_EPCI!$E$2:$E$93, "oupsi") -> 24370 | E32: =COUNTIF(Communes_HDF!E:E, Décision!A25) -> 20 | F32: =SUMIF(Communes_HDF!E:E,Décision!A25,Communes_HDF!G:G) -> 138.3 | G32: =_xlfn.XLOOKUP(A32, INSEE_EPCI!$A$2:$A$93, INSEE_EPCI!$D$2:$D$93, "oupsi") -> 103106 | H32: =(INSEE_EPCI!D21-INSEE_EPCI!C21)/INSEE_EPCI!C21 -> 0.004863216 | I32: =C32*G32/100 -> 19796.352 | J32: =G32/F32 -> 745.52422
A33: =INSEE_EPCI!A84 -> 200069672 | B33: =INSEE_EPCI!B84 -> CC du Ternois | C33: =_xlfn.XLOOKUP(A33, INSEE_EPCI!$A$2:$A$93, INSEE_EPCI!$F$2:$F$93, "oupsi") -> 18.9 | D33: =_xlfn.XLOOKUP(A33, INSEE_EPCI!$A$2:$A$93, INSEE_EPCI!$E$2:$E$93, "oupsi") -> 23180 | E33: =COUNTIF(Communes_HDF!E:E, Décision!A88) -> 20 | F33: =SUMIF(Communes_HDF!E:E,Décision!A88,Communes_HDF!G:G) -> 211.15 | G33: =_xlfn.XLOOKUP(A33, INSEE_EPCI!$A$2:$A$93, INSEE_EPCI!$D$2:$D$93, "oupsi") -> 36913 | H33: =(INSEE_EPCI!D84-INSEE_EPCI!C84)/INSEE_EPCI!C84 -> -0.037821916 | I33: =C33*G33/100 -> 6976.557 | J33: =G33/F33 -> 174.81885
A34: =INSEE_EPCI!A16 -> 200070993 | B34: =INSEE_EPCI!B16 -> CA de la Baie de Somme | C34: =_xlfn.XLOOKUP(A34, INSEE_EPCI!$A$2:$A$93, INSEE_EPCI!$F$2:$F$93, "oupsi") -> 18.5 | D34: =_xlfn.XLOOKUP(A34, INSEE_EPCI!$A$2:$A$93, INSEE_EPCI!$E$2:$E$93, "oupsi") -> 23410 | E34: =COUNTIF(Communes_HDF!E:E, Décision!A20) -> 35 | F34: =SUMIF(Communes_HDF!E:E,Décision!A20,Communes_HDF!G:G) -> 235.58 | G34: =_xlfn.XLOOKUP(A34, INSEE_EPCI!$A$2:$A$93, INSEE_EPCI!$D$2:$D$93, "oupsi") -> 47572 | H34: =(INSEE_EPCI!D16-INSEE_EPCI!C16)/INSEE_EPCI!C16 -> -0.032912525 | I34: =C34*G34/100 -> 8800.82 | J34: =G34/F34 -> 201.93565
A35: =INSEE_EPCI!A80 -> 240200493 | B35: =INSEE_EPCI!B80 -> CC du Pays du Vermandois | C35: =_xlfn.XLOOKUP(A35, INSEE_EPCI!$A$2:$A$93, INSEE_EPCI!$F$2:$F$93, "oupsi") -> 18.2 | D35: =_xlfn.XLOOKUP(A35, INSEE_EPCI!$A$2:$A$93, INSEE_EPCI!$E$2:$E$93, "oupsi") -> 23320 | E35: =COUNTIF(Communes_HDF!E:E, Décision!A84) -> 40 | F35: =SUMIF(Communes_HDF!E:E,Décision!A84,Communes_HDF!G:G) -> 448.54 | G35: =_xlfn.XLOOKUP(A35, INSEE_EPCI!$A$2:$A$93, INSEE_EPCI!$D$2:$D$93, "oupsi") -> 30577 | H35: =(INSEE_EPCI!D80-INSEE_EPCI!C80)/INSEE_EPCI!C80 -> -0.020187778 | I35: =C35*G35/100 -> 5565.014 | J35: =G35/F35 -> 68.170063
A36: =INSEE_EPCI!A54 -> 200044030 | B36: =INSEE_EPCI!B54 -> CC des 7 Vallées | C36: =_xlfn.XLOOKUP(A36, INSEE_EPCI!$A$2:$A$93, INSEE_EPCI!$F$2:$F$93, "oupsi") -> 17.9 | D36: =_xlfn.XLOOKUP(A36, INSEE_EPCI!$A$2:$A$93, INSEE_EPCI!$E$2:$E$93, "oupsi") -> 23150 | E36: =COUNTIF(Communes_HDF!E:E, Décision!A58) -> 32 | F36: =SUMIF(Communes_HDF!E:E,Décision!A58,Communes_HDF!G:G) -> 328.37 | G36: =_xlfn.XLOOKUP(A36, INSEE_EPCI!$A$2:$A$93, INSEE_EPCI!$D$2:$D$93, "oupsi") -> 29526 | H36: =(INSEE_EPCI!D54-INSEE_EPCI!C54)/INSEE_EPCI!C54 -> -0.0068283494 | I36: =C36*G36/100 -> 5285.154 | J36: =G36/F36 -> 89.916862
A37: =INSEE_EPCI!A25 -> 200069037 | B37: =INSEE_EPCI!B25 -> CA du Pays de Saint-Omer | C37: =_xlfn.XLOOKUP(A37, INSEE_EPCI!$A$2:$A$93, INSEE_EPCI!$F$2:$F$93, "oupsi") -> 17.6 | D37: =_xlfn.XLOOKUP(A37, INSEE_EPCI!$A$2:$A$93, INSEE_EPCI!$E$2:$E$93, "oupsi") -> 23440 | E37: =COUNTIF(Communes_HDF!E:E, Décision!A29) -> 42 | F37: =SUMIF(Communes_HDF!E:E,Décision!A29,Communes_HDF!G:G) -> 267.53 | G37: =_xlfn.XLOOKUP(A37, INSEE_EPCI!$A$2:$A$93, INSEE_EPCI!$D$2:$D$93, "oupsi") -> 104207 | H37: =(INSEE_EPCI!D25-INSEE_EPCI!C25)/INSEE_EPCI!C25 -> -0.014525784 | I37: =C37*G37/100 -> 18340.432 | J37: =G37/F37 -> 389.51519
A38: =INSEE_EPCI!A14 -> 200068500 | B38: =INSEE_EPCI!B14 -> CA de Cambrai | C38: =_xlfn.XLOOKUP(A38, INSEE_EPCI!$A$2:$A$93, INSEE_EPCI!$F$2:$F$93, "oupsi") -> 17.6 | D38: =_xlfn.XLOOKUP(A38, INSEE_EPCI!$A$2:$A$93, INSEE_EPCI!$E$2:$E$93, "oupsi") -> 23780 | E38: =COUNTIF(Communes_HDF!E:E, Décision!A18) -> 14 | F38: =SUMIF(Communes_HDF!E:E,Décision!A18,Communes_HDF!G:G) -> 111.99 | G38: =_xlfn.XLOOKUP(A38, INSEE_EPCI!$A$2:$A$93, INSEE_EPCI!$D$2:$D$93, "oupsi") -> 80120 | H38: =(INSEE_EPCI!D14-INSEE_EPCI!C14)/INSEE_EPCI!C14 -> -0.021805484 | I38: =C38*G38/100 -> 14101.12 | J38: =G38/F38 -> 715.42102
A39: =INSEE_EPCI!A48 -> 200037059 | B39: =INSEE_EPCI!B48 -> CC de la Haute Somme (Combles - Péronne - Roisel) | C39: =_xlfn.XLOOKUP(A39, INSEE_EPCI!$A$2:$A$93, INSEE_EPCI!$F$2:$F$93, "oupsi") -> 17.2 | D39: =_xlfn.XLOOKUP(A39, INSEE_EPCI!$A$2:$A$93, INSEE_EPCI!$E$2:$E$93, "oupsi") -> 23420 | E39: =COUNTIF(Communes_HDF!E:E, Décision!A52) -> 52 | F39: =SUMIF(Communes_HDF!E:E,Décision!A52,Communes_HDF!G:G) -> 466.44 | G39: =_xlfn.XLOOKUP(A39, INSEE_EPCI!$A$2:$A$93, INSEE_EPCI!$D$2:$D$93, "oupsi") -> 26393 | H39: =(INSEE_EPCI!D48-INSEE_EPCI!C48)/INSEE_EPCI!C48 -> -0.037980682 | I39: =C39*G39/100 -> 4539.596 | J39: =G39/F39 -> 56.583912
A40: =INSEE_EPCI!A45 -> 200070985 | B40: =INSEE_EPCI!B45 -> CC de l'Est de la Somme | C40: =_xlfn.XLOOKUP(A40, INSEE_EPCI!$A$2:$A$93, INSEE_EPCI!$F$2:$F$93, "oupsi") -> 17 | D40: =_xlfn.XLOOKUP(A40, INSEE_EPCI!$A$2:$A$93, INSEE_EPCI!$E$2:$E$93, "oupsi") -> 23140 | E40: =COUNTIF(Communes_HDF!E:E, Décision!A49) -> 15 | F40: =SUMIF(Communes_HDF!E:E,Décision!A49,Communes_HDF!G:G) -> 117.19 | G40: =_xlfn.XLOOKUP(A40, INSEE_EPCI!$A$2:$A$93, INSEE_EPCI!$D$2:$D$93, "oupsi") -> 19637 | H40: =(INSEE_EPCI!D45-INSEE_EPCI!C45)/INSEE_EPCI!C45 -> -0.036977098 | I40: =C40*G40/100 -> 3338.29 | J40: =G40/F40 -> 167.56549
A41: =INSEE_EPCI!A69 -> 200069235 | B41: =INSEE_EPCI!B69 -> CC du Haut Pays du Montreuillois | C41: =_xlfn.XLOOKUP(A41, INSEE_EPCI!$A$2:$A$93, INSEE_EPCI!$F$2:$F$93, "oupsi") -> 17 | D41: =_xlfn.XLOOKUP(A41, INSEE_EPCI!$A$2:$A$93, INSEE_EPCI!$E$2:$E$93, "oupsi") -> 23240 | E41: =COUNTIF(Communes_HDF!E:E, Décision!A73) -> 56 | F41: =SUMIF(Communes_HDF!E:E,Décision!A73,Communes_HDF!G:G) -> 396.56 | G41: =_xlfn.XLOOKUP(A41, INSEE_EPCI!$A$2:$A$93, INSEE_EPCI!$D$2:$D$93, "oupsi") -> 15781 | H41: =(INSEE_EPCI!D69-INSEE_EPCI!C69)/INSEE_EPCI!C69 -> 0.0025411346 | I41: =C41*G41/100 -> 2682.77 | J41: =G41/F41 -> 39.794735
...

Sheet Feuil2
B1: Nom_EPCI | C1: taux de pauvreté
B2: CA Creil Sud Oise | C2: 33.5
B3: CC du Sud Avesnois | C3: 29.7
B4: CA Maubeuge Val de Sambre | C4: 28.6
B5: CC des Trois Rivières | C5: 26
B6: CA de Lens - Liévin | C6: 25.3
B7: CA Valenciennes Métropole | C7: 25
B8: CC des Portes de la Thiérache | C8: 24
B9: CC Thiérache Sambre et Oise | C9: 24
B10: CA du Saint-Quentinois | C10: 24
B11: CA GrandSoissons Agglomération | C11: 23.9
B12: CA de la Porte du Hainaut | C12: 23.6
B13: CA Amiens Métropole | C13: 23.5
... B93: CC du Vexin-Thelle | C93: 7

Sheet Feuil3
A3: Nom_EPCI | B3: Somme de taux de pauvreté | E3: Nom_EPCI | F3: Somme de taux de pauvreté
A4: CA Amiens Métropole | B4: 23.5 | E4: CA Amiens Métropole | F4: 23.5
A5: CA Chauny Tergnier La Fère | B5: 21.6 | E5: CA Chauny Tergnier La Fère | F5: 21.6
